<?xml version="1.0" ?>
<sdf version="1.10">
    <!-- Osoyoo Robot -->
    <model name='osoyoo' canonical_link='chassis'>

      <!-- Chassis -->
      <link name='chassis'>
        <pose relative_to='__model__'>0 0 0 0 0 0</pose>
        <inertial>
          <mass>1.0</mass>
          <inertia>
            <ixx>0.001</ixx> <ixy>0</ixy> <ixz>0</ixz>
            <iyy>0.001</iyy> <iyz>0</iyz>
            <izz>0.001</izz>
          </inertia>
        </inertial>
        <visual name='visual'>
          <geometry>
            <box><size>0.205 0.167 0.12</size></box>
          </geometry>
          <material>
            <ambient>0.0 0.0 1.0 1</ambient>
            <diffuse>0.0 0.0 1.0 1</diffuse>
            <specular>0.0 0.0 1.0 1</specular>
          </material>
        </visual>
        <collision name='collision'>
          <geometry>
            <box><size>0.205 0.167 0.12</size></box>
          </geometry>
        </collision>
      </link>

      <!-- Left Wheel -->
      <link name='left_wheel'>
        <pose relative_to="chassis">0.05 0.0835 -0.0375 -1.5707 0 0</pose>
        <inertial>
          <mass>0.05</mass>
          <inertia>
            <ixx>1e-4</ixx> <ixy>0</ixy> <ixz>0</ixz>
            <iyy>1e-4</iyy> <iyz>0</iyz>
            <izz>1e-4</izz>
          </inertia>
        </inertial>
        <visual name='visual'>
          <geometry>
            <cylinder>
              <radius>0.0325</radius>
              <length>0.02</length>
            </cylinder>
          </geometry>
          <material>
            <ambient>1.0 0.0 0.0 1</ambient>
            <diffuse>1.0 0.0 0.0 1</diffuse>
            <specular>1.0 0.0 0.0 1</specular>
          </material>
        </visual>
        <collision name='collision'>
          <geometry>
            <cylinder>
              <radius>0.0325</radius>
              <length>0.02</length>
            </cylinder>
          </geometry>
        </collision>
      </link>

      <!-- Right Wheel -->
      <link name='right_wheel'>
        <pose relative_to="chassis">0.05 -0.0835 -0.0375 -1.5707 0 0</pose>
        <inertial>
          <mass>0.05</mass>
          <inertia>
            <ixx>1e-4</ixx> <ixy>0</ixy> <ixz>0</ixz>
            <iyy>1e-4</iyy> <iyz>0</iyz>
            <izz>1e-4</izz>
          </inertia>
        </inertial>
        <visual name='visual'>
          <geometry>
            <cylinder>
              <radius>0.0325</radius>
              <length>0.02</length>
            </cylinder>
          </geometry>
          <material>
            <ambient>1.0 0.0 0.0 1</ambient>
            <diffuse>1.0 0.0 0.0 1</diffuse>
            <specular>1.0 0.0 0.0 1</specular>
          </material>
        </visual>
        <collision name='collision'>
          <geometry>
            <cylinder>
              <radius>0.0325</radius>
              <length>0.02</length>
            </cylinder>
          </geometry>
        </collision>
      </link>

      <!-- Caster -->
      <frame name="caster_frame" attached_to='chassis'>
        <pose>-0.09 0 -0.06 0 0 0</pose>
      </frame>
      <link name='caster'>
        <pose relative_to='caster_frame'/>
        <inertial>
          <mass>0.02</mass>
          <inertia>
            <ixx>1e-5</ixx> <ixy>0</ixy> <ixz>0</ixz>
            <iyy>1e-5</iyy> <iyz>0</iyz>
            <izz>1e-5</izz>
          </inertia>
        </inertial>
        <visual name='visual'>
          <geometry><sphere><radius>0.01</radius></sphere></geometry>
          <material>
            <ambient>0.0 1.0 0.0 1</ambient>
            <diffuse>0.0 1.0 0.0 1</diffuse>
            <specular>0.0 1.0 0.0 1</specular>
          </material>
        </visual>
        <collision name='collision'>
          <geometry><sphere><radius>0.01</radius></sphere></geometry>
        </collision>
      </link>

      <!-- Joints -->
      <joint name='left_wheel_joint' type='revolute'>
        <pose relative_to='left_wheel'/>
        <parent>chassis</parent>
        <child>left_wheel</child>
        <axis>
          <xyz expressed_in='__model__'>0 1 0</xyz>
          <limit><lower>-1e16</lower><upper>1e16</upper></limit>
        </axis>
      </joint>
      <joint name='right_wheel_joint' type='revolute'>
        <pose relative_to='right_wheel'/>
        <parent>chassis</parent>
        <child>right_wheel</child>
        <axis>
          <xyz expressed_in='__model__'>0 1 0</xyz>
          <limit><lower>-1e16</lower><upper>1e16</upper></limit>
        </axis>
      </joint>
      <joint name='caster_wheel' type='ball'>
        <parent>chassis</parent>
        <child>caster</child>
      </joint>

      <!-- DiffDrive plugin -->
      <plugin filename="gz-sim-diff-drive-system" name="gz::sim::systems::DiffDrive">
        <left_joint>left_wheel_joint</left_joint>
        <right_joint>right_wheel_joint</right_joint>
        <wheel_separation>0.147</wheel_separation>
        <wheel_radius>0.0325</wheel_radius>
        <odom_topic>odom</odom_topic>
        <odom_publish_frequency>10</odom_publish_frequency>
        <topic>cmd_vel</topic>
        <tf_topic>tf</tf_topic>
        <odom_frame>odom</odom_frame>
        <robot_base_frame>chassis</robot_base_frame>
   
      </plugin>
      
      <plugin 
        filename="gz-sim-odometry-publisher-system" 
        name = "gz::sim::systems::OdometryPublisher">
      </plugin>

    </model>
</sdf>
